<?xml version="1.0"?>
<sdf version='1.11'>
  <model name='UF_ROBOT'>
    <joint name='world_joint' type='fixed'>
      <pose relative_to='__model__'>0 0 0 0 0 0</pose>
      <parent>world</parent>
      <child>link_base</child>
    </joint>
    <link name='link_base'>
      <pose relative_to='world_joint'>0 0 0 0 0 0</pose>
      <inertial>
        <pose>-0.021131 -0.0016302000000000001 0.056487999999999997 0 0 0</pose>
        <mass>0.88556000000000001</mass>
        <inertia>
          <ixx>0.0030595000000000002</ixx>
          <ixy>0.00012259</ixy>
          <ixz>-0.00062704999999999998</ixz>
          <iyy>0.0037783000000000001</iyy>
          <iyz>0.00027022999999999999</iyz>
          <izz>0.0020125</izz>
        </inertia>
      </inertial>
      <collision name='link_base_collision'>
        <pose>0 0 0 0 0 0</pose>
        <geometry>
          <mesh>
            <scale>1 1 1</scale>
            <uri>model://xarm_description/meshes/xarm7/visual/link_base.obj</uri>
          </mesh>
        </geometry>
        <surface>
          <contact>
            <ode />
          </contact>
          <friction>
            <ode />
          </friction>
        </surface>
      </collision>
      <visual name='link_base_visual'>
        <pose>0 0 0 0 0 0</pose>
        <geometry>
          <mesh>
            <scale>1 1 1</scale>
            <uri>model://xarm_description/meshes/xarm7/visual/link_base.obj</uri>
          </mesh>
        </geometry>
        <material>
          <diffuse>1 1 1 1</diffuse>
          <ambient>1 1 1 1</ambient>
        </material>
      </visual>

    </link>
    <joint name='joint1' type='revolute'>
      <pose relative_to='link_base'>0 0 0.26700000000000002 0 0 0</pose>
      <parent>link_base</parent>
      <child>link1</child>
      <axis>
        <xyz>0 0 1</xyz>
        <limit>
          <lower>-6.2831853071795862</lower>
          <upper>6.2831853071795862</upper>
          <effort>50</effort>
          <velocity>3.1400000000000001</velocity>
        </limit>
        <dynamics>
          <damping>10</damping>
          <friction>1</friction>
          <spring_reference>0</spring_reference>
          <spring_stiffness>0</spring_stiffness>
        </dynamics>
      </axis>
    </joint>
    <link name='link1'>
      <pose relative_to='joint1'>0 0 0 0 0 0</pose>
      <inertial>
        <pose>-0.00020000000000000001 0.029049999999999999 -0.012330000000000001 0 0 0</pose>
        <mass>2.3820000000000001</mass>
        <inertia>
          <ixx>0.0056905000000000002</ixx>
          <ixy>-1.579e-05</ixy>
          <ixz>5.1250000000000001e-06</ixz>
          <iyy>0.0049566000000000002</iyy>
          <iyz>-0.00087337799999999996</iyz>
          <izz>0.003316654</izz>
        </inertia>
      </inertial>
      <collision name='link1_collision'>
        <pose>0 0 0 0 0 0</pose>
        <geometry>
          <mesh>
            <scale>1 1 1</scale>
            <uri>model://xarm_description/meshes/xarm7/visual/link1.obj</uri>
          </mesh>
        </geometry>
        <surface>
          <contact>
            <ode />
          </contact>
          <friction>
            <ode />
          </friction>
        </surface>
      </collision>
      <visual name='link1_visual'>
        <pose>0 0 0 0 0 0</pose>
        <geometry>
          <mesh>
            <scale>1 1 1</scale>
            <uri>model://xarm_description/meshes/xarm7/visual/link1.obj</uri>
          </mesh>
        </geometry>
        <material>
          <diffuse>1 1 1 1</diffuse>
          <ambient>1 1 1 1</ambient>
        </material>
      </visual>

    </link>
    <joint name='joint2' type='revolute'>
      <pose relative_to='link1'>0 0 0 -1.5708 0 0</pose>
      <parent>link1</parent>
      <child>link2</child>
      <axis>
        <xyz>0 0 1</xyz>
        <limit>
          <lower>-2.0590000000000002</lower>
          <upper>2.0943999999999998</upper>
          <effort>50</effort>
          <velocity>3.1400000000000001</velocity>
        </limit>
        <dynamics>
          <damping>10</damping>
          <friction>1</friction>
          <spring_reference>0</spring_reference>
          <spring_stiffness>0</spring_stiffness>
        </dynamics>
      </axis>
    </joint>
    <link name='link2'>
      <pose relative_to='joint2'>0 0 0 0 0 0</pose>
      <inertial>
        <pose>0.00022000000000000001 -0.12856000000000001 0.017350000000000001 0 0 0</pose>
        <mass>1.869</mass>
        <inertia>
          <ixx>0.0095989000000000005</ixx>
          <ixy>1.5409999999999999e-06</ixy>
          <ixz>5.5600000000000001e-06</ixz>
          <iyy>0.0038247200000000002</iyy>
          <iyz>-0.0031715599999999999</iyz>
          <izz>0.0075656689999999997</izz>
        </inertia>
      </inertial>
      <collision name='link2_collision'>
        <pose>0 0 0 0 0 0</pose>
        <geometry>
          <mesh>
            <scale>1 1 1</scale>
            <uri>model://xarm_description/meshes/xarm7/visual/link2.obj</uri>
          </mesh>
        </geometry>
        <surface>
          <contact>
            <ode />
          </contact>
          <friction>
            <ode />
          </friction>
        </surface>
      </collision>
      <visual name='link2_visual'>
        <pose>0 0 0 0 0 0</pose>
        <geometry>
          <mesh>
            <scale>1 1 1</scale>
            <uri>model://xarm_description/meshes/xarm7/visual/link2.obj</uri>
          </mesh>
        </geometry>
        <material>
          <diffuse>1 1 1 1</diffuse>
          <ambient>1 1 1 1</ambient>
        </material>
      </visual>

    </link>
    <joint name='joint3' type='revolute'>
      <pose relative_to='link2'>0 -0.29299999999999998 0 1.5708 0 0</pose>
      <parent>link2</parent>
      <child>link3</child>
      <axis>
        <xyz>0 0 1</xyz>
        <limit>
          <lower>-6.2831853071795862</lower>
          <upper>6.2831853071795862</upper>
          <effort>30</effort>
          <velocity>3.1400000000000001</velocity>
        </limit>
        <dynamics>
          <damping>5</damping>
          <friction>1</friction>
          <spring_reference>0</spring_reference>
          <spring_stiffness>0</spring_stiffness>
        </dynamics>
      </axis>
    </joint>
    <link name='link3'>
      <pose relative_to='joint3'>0 0 0 0 0 0</pose>
      <inertial>
        <pose>0.046600000000000003 -0.024629999999999999 -0.0076800000000000002 0 0 0</pose>
        <mass>1.6383000000000001</mass>
        <inertia>
          <ixx>0.00310955</ixx>
          <ixy>0.00030836999999999998</ixy>
          <ixz>-0.00058452999999999999</ixz>
          <iyy>0.0026448299999999999</iyy>
          <iyz>0.000338893</iyz>
          <izz>0.0026624000000000001</izz>
        </inertia>
      </inertial>
      <collision name='link3_collision'>
        <pose>0 0 0 0 0 0</pose>
        <geometry>
          <mesh>
            <scale>1 1 1</scale>
            <uri>model://xarm_description/meshes/xarm7/visual/link3.obj</uri>
          </mesh>
        </geometry>
        <surface>
          <contact>
            <ode />
          </contact>
          <friction>
            <ode />
          </friction>
        </surface>
      </collision>
      <visual name='link3_visual'>
        <pose>0 0 0 0 0 0</pose>
        <geometry>
          <mesh>
            <scale>1 1 1</scale>
            <uri>model://xarm_description/meshes/xarm7/visual/link3.obj</uri>
          </mesh>
        </geometry>
        <material>
          <diffuse>1 1 1 1</diffuse>
          <ambient>1 1 1 1</ambient>
        </material>
      </visual>

    </link>
    <joint name='joint4' type='revolute'>
      <pose relative_to='link3'>0.052499999999999998 0 0 1.5708 0 0</pose>
      <parent>link3</parent>
      <child>link4</child>
      <axis>
        <xyz>0 0 1</xyz>
        <limit>
          <lower>-0.19198000000000001</lower>
          <upper>3.927</upper>
          <effort>30</effort>
          <velocity>3.1400000000000001</velocity>
        </limit>
        <dynamics>
          <damping>5</damping>
          <friction>1</friction>
          <spring_reference>0</spring_reference>
          <spring_stiffness>0</spring_stiffness>
        </dynamics>
      </axis>
    </joint>
    <link name='link4'>
      <pose relative_to='joint4'>0 0 0 0 0 0</pose>
      <inertial>
        <pose>0.070470000000000005 -0.11575000000000001 0.012 0 0 0</pose>
        <mass>1.7269000000000001</mass>
        <inertia>
          <ixx>0.0058890000000000001</ixx>
          <ixy>0.00137112</ixy>
          <ixz>0.00088143</ixz>
          <iyy>0.0035970300000000002</iyy>
          <iyz>-0.0017621550000000001</iyz>
          <izz>0.0054324400000000002</izz>
        </inertia>
      </inertial>
      <collision name='link4_collision'>
        <pose>0 0 0 0 0 0</pose>
        <geometry>
          <mesh>
            <scale>1 1 1</scale>
            <uri>model://xarm_description/meshes/xarm7/visual/link4.obj</uri>
          </mesh>
        </geometry>
        <surface>
          <contact>
            <ode />
          </contact>
          <friction>
            <ode />
          </friction>
        </surface>
      </collision>
      <visual name='link4_visual'>
        <pose>0 0 0 0 0 0</pose>
        <geometry>
          <mesh>
            <scale>1 1 1</scale>
            <uri>model://xarm_description/meshes/xarm7/visual/link4.obj</uri>
          </mesh>
        </geometry>
        <material>
          <diffuse>1 1 1 1</diffuse>
          <ambient>1 1 1 1</ambient>
        </material>
      </visual>

    </link>
    <joint name='joint5' type='revolute'>
      <pose relative_to='link4'>0.077499999999999999 -0.34250000000000003 0 1.5708 0 0</pose>
      <parent>link4</parent>
      <child>link5</child>
      <axis>
        <xyz>0 0 1</xyz>
        <limit>
          <lower>-6.2831853071795862</lower>
          <upper>6.2831853071795862</upper>
          <effort>30</effort>
          <velocity>3.1400000000000001</velocity>
        </limit>
        <dynamics>
          <damping>5</damping>
          <friction>1</friction>
          <spring_reference>0</spring_reference>
          <spring_stiffness>0</spring_stiffness>
        </dynamics>
      </axis>
    </joint>
    <link name='link5'>
      <pose relative_to='joint5'>0 0 0 0 0 0</pose>
      <inertial>
        <pose>-0.00032000000000000003 0.016039999999999999 -0.025999999999999999 0 0 0</pose>
        <mass>1.3203</mass>
        <inertia>
          <ixx>0.0053466499999999997</ixx>
          <ixy>1.5116999999999999e-05</ixy>
          <ixz>-3.6899999999999998e-07</ixz>
          <iyy>0.0049779000000000004</iyy>
          <iyz>-0.00022132</iyz>
          <izz>0.0013623999999999999</izz>
        </inertia>
      </inertial>
      <collision name='link5_collision'>
        <pose>0 0 0 0 0 0</pose>
        <geometry>
          <mesh>
            <scale>1 1 1</scale>
            <uri>model://xarm_description/meshes/xarm7/visual/link5.obj</uri>
          </mesh>
        </geometry>
        <surface>
          <contact>
            <ode />
          </contact>
          <friction>
            <ode />
          </friction>
        </surface>
      </collision>
      <visual name='link5_visual'>
        <pose>0 0 0 0 0 0</pose>
        <geometry>
          <mesh>
            <scale>1 1 1</scale>
            <uri>model://xarm_description/meshes/xarm7/visual/link5.obj</uri>
          </mesh>
        </geometry>
        <material>
          <diffuse>1 1 1 1</diffuse>
          <ambient>1 1 1 1</ambient>
        </material>
      </visual>

    </link>
    <joint name='joint6' type='revolute'>
      <pose relative_to='link5'>0 0 0 1.5708 0 0</pose>
      <parent>link5</parent>
      <child>link6</child>
      <axis>
        <xyz>0 0 1</xyz>
        <limit>
          <lower>-1.6929700000000001</lower>
          <upper>3.1415926535897931</upper>
          <effort>20</effort>
          <velocity>3.1400000000000001</velocity>
        </limit>
        <dynamics>
          <damping>2</damping>
          <friction>1</friction>
          <spring_reference>0</spring_reference>
          <spring_stiffness>0</spring_stiffness>
        </dynamics>
      </axis>
    </joint>
    <link name='link6'>
      <pose relative_to='joint6'>0 0 0 0 0 0</pose>
      <inertial>
        <pose>0.064689999999999998 0.032779999999999997 0.021409999999999998 0 0 0</pose>
        <mass>1.325</mass>
        <inertia>
          <ixx>0.0014744999999999999</ixx>
          <ixy>-0.00048799999999999999</ixy>
          <ixz>0.00029530000000000002</ixz>
          <iyy>0.0019036999999999999</iyy>
          <iyz>0.00014749000000000001</iyz>
          <izz>0.0023652</izz>
        </inertia>
      </inertial>
      <collision name='link6_collision'>
        <pose>0 0 0 0 0 0</pose>
        <geometry>
          <mesh>
            <scale>1 1 1</scale>
            <uri>model://xarm_description/meshes/xarm7/visual/link6.obj</uri>
          </mesh>
        </geometry>
        <surface>
          <contact>
            <ode />
          </contact>
          <friction>
            <ode />
          </friction>
        </surface>
      </collision>
      <visual name='link6_visual'>
        <pose>0 0 0 0 0 0</pose>
        <geometry>
          <mesh>
            <scale>1 1 1</scale>
            <uri>model://xarm_description/meshes/xarm7/visual/link6.obj</uri>
          </mesh>
        </geometry>
        <material>
          <diffuse>1 1 1 1</diffuse>
          <ambient>1 1 1 1</ambient>
        </material>
      </visual>

    </link>
    <joint name='joint7' type='revolute'>
      <pose relative_to='link6'>0.075999999999999998 0.097000000000000003 0 -1.5708 0 0</pose>
      <parent>link6</parent>
      <child>link7</child>
      <axis>
        <xyz>0 0 1</xyz>
        <limit>
          <lower>-6.2831853071795862</lower>
          <upper>6.2831853071795862</upper>
          <effort>20</effort>
          <velocity>3.1400000000000001</velocity>
        </limit>
        <dynamics>
          <damping>2</damping>
          <friction>1</friction>
          <spring_reference>0</spring_reference>
          <spring_stiffness>0</spring_stiffness>
        </dynamics>
      </axis>
    </joint>
    <link name='link7'>
      <pose relative_to='joint7'>0 0 0 0 0 0</pose>
      <inertial>
        <pose>-0.00049842912530215298 -0.0030252171735342059 0.033930299173646643 0 0 0</pose>
        <mass>0.71156000000000008</mass>
        <inertia>
          <ixx>0.001017703706058532</ixx>
          <ixy>8.0983154028811108e-07</ixy>
          <ixz>7.6536219903910084e-06</ixz>
          <iyy>0.00083998686948102985</iyy>
          <iyz>-5.2140264654095912e-05</iyz>
          <izz>0.00039160781810245788</izz>
        </inertia>
      </inertial>
      <collision name='link7_collision'>
        <pose>0 0 0 0 0 0</pose>
        <geometry>
          <mesh>
            <scale>1 1 1</scale>
            <uri>model://xarm_description/meshes/end_tool/collision/end_tool.obj</uri>
          </mesh>
        </geometry>
        <surface>
          <contact>
            <ode />
          </contact>
          <friction>
            <ode />
          </friction>
        </surface>
      </collision>
      <collision name='link7_fixed_joint_lump__xarm_gripper_base_link_collision_1'>
        <pose>0 0 0 0 0 0</pose>
        <geometry>
          <mesh>
            <scale>1 1 1</scale>
            <uri>model://xarm_description/meshes/gripper/xarm/base_link.obj</uri>
          </mesh>
        </geometry>
        <surface>
          <contact>
            <ode />
          </contact>
          <friction>
            <ode />
          </friction>
        </surface>
      </collision>
      <visual name='link7_visual'>
        <pose>0 0 0 0 0 0</pose>
        <geometry>
          <mesh>
            <scale>1 1 1</scale>
            <uri>model://xarm_description/meshes/xarm7/visual/link7.obj</uri>
          </mesh>
        </geometry>
        <material>
          <diffuse>0.941250026 0.941250026 0.941250026 1</diffuse>
          <ambient>0.941250026 0.941250026 0.941250026 1</ambient>
        </material>
      </visual>
      <visual name='link7_fixed_joint_lump__xarm_gripper_base_link_visual_1'>
        <pose>0 0 0 0 0 0</pose>
        <geometry>
          <mesh>
            <scale>1 1 1</scale>
            <uri>model://xarm_description/meshes/gripper/xarm/base_link.obj</uri>
          </mesh>
        </geometry>
        <material>
          <diffuse>1 1 1 1</diffuse>
          <ambient>1 1 1 1</ambient>
        </material>
      </visual>
    </link>
    <joint name='drive_joint' type='revolute'>
      <pose relative_to='link7'>0 0.035000000000000003 0.059097999999999998 0 0 0</pose>
      <parent>link7</parent>
      <child>left_outer_knuckle</child>
      <axis>
        <xyz>1 0 0</xyz>
        <limit>
          <lower>0</lower>
          <upper>0.84999999999999998</upper>
          <effort>50</effort>
          <velocity>2</velocity>
        </limit>
        <dynamics>
          <spring_reference>0</spring_reference>
          <spring_stiffness>0</spring_stiffness>
        </dynamics>
      </axis>
    </joint>
    <link name='left_outer_knuckle'>
      <pose relative_to='drive_joint'>0 0 0 0 0 0</pose>
      <inertial>
        <pose>2.9948000000000001e-14 0.021558999999999998 0.015181 0 0 0</pose>
        <mass>0.033618000000000002</mass>
        <inertia>
          <ixx>1.9111e-05</ixx>
          <ixy>-1.8803000000000001e-17</ixy>
          <ixz>-1.1002e-17</ixz>
          <iyy>6.6255999999999997e-06</iyy>
          <iyz>-7.3007999999999996e-06</iyz>
          <izz>1.3185e-05</izz>
        </inertia>
      </inertial>
      <collision name='left_outer_knuckle_collision'>
        <pose>0 0 0 0 0 0</pose>
        <geometry>
          <mesh>
            <scale>1 1 1</scale>
            <uri>model://xarm_description/meshes/gripper/xarm/left_outer_knuckle.obj</uri>
          </mesh>
        </geometry>
        <surface>
          <contact>
            <ode />
          </contact>
          <friction>
            <ode />
          </friction>
        </surface>
      </collision>
      <visual name='left_outer_knuckle_visual'>
        <pose>0 0 0 0 0 0</pose>
        <geometry>
          <mesh>
            <scale>1 1 1</scale>
            <uri>model://xarm_description/meshes/gripper/xarm/left_outer_knuckle.obj</uri>
          </mesh>
        </geometry>
        <material>
          <diffuse>0.941250026 0.941250026 0.941250026 1</diffuse>
          <ambient>0.941250026 0.941250026 0.941250026 1</ambient>
        </material>
      </visual>

    </link>
    <joint name='left_finger_joint' type='revolute'>
      <pose relative_to='left_outer_knuckle'>0 0.035465000000000003 0.042039 0 0 0</pose>
      <parent>left_outer_knuckle</parent>
      <child>left_finger</child>
      <axis>
        <xyz>-1 0 0</xyz>
        <mimic joint='drive_joint'>
          <multiplier>1</multiplier>
          <offset>0</offset>
          <reference>0</reference>
        </mimic>
        <limit>
          <lower>0</lower>
          <upper>0.84999999999999998</upper>
          <effort>50</effort>
          <velocity>2</velocity>
        </limit>
        <dynamics>
          <spring_reference>0</spring_reference>
          <spring_stiffness>0</spring_stiffness>
        </dynamics>
      </axis>
    </joint>
    <link name='left_finger'>
      <pose relative_to='left_finger_joint'>0 0 0 0 0 0</pose>
      <inertial>
        <pose>-2.4536e-14 -0.016413000000000001 0.029257999999999999 0 0 0</pose>
        <mass>0.048304</mass>
        <inertia>
          <ixx>1.7493e-05</ixx>
          <ixy>-4.2156000000000001e-19</ixy>
          <ixz>6.9163999999999997e-18</ixz>
          <iyy>1.7224999999999999e-05</iyy>
          <iyz>4.6433000000000001e-06</iyz>
          <izz>5.1466e-06</izz>
        </inertia>
      </inertial>
      <collision name='left_finger_collision'>
        <pose>0 0 0 0 0 0</pose>
        <geometry>
          <mesh>
            <scale>1 1 1</scale>
            <uri>model://xarm_description/meshes/gripper/xarm/left_finger.obj</uri>
          </mesh>
        </geometry>
        <surface>
          <contact>
            <ode />
          </contact>
          <friction>
            <ode />
          </friction>
        </surface>
      </collision>
      <visual name='left_finger_visual'>
        <pose>0 0 0 0 0 0</pose>
        <geometry>
          <mesh>
            <scale>1 1 1</scale>
            <uri>model://xarm_description/meshes/gripper/xarm/left_finger.obj</uri>
          </mesh>
        </geometry>
        <material>
          <diffuse>0.941250026 0.941250026 0.941250026 1</diffuse>
          <ambient>0.941250026 0.941250026 0.941250026 1</ambient>
        </material>
      </visual>

    </link>
    <joint name='left_inner_knuckle_joint' type='revolute'>
      <pose relative_to='link7'>0 0.02 0.074097999999999997 0 0 0</pose>
      <parent>link7</parent>
      <child>left_inner_knuckle</child>
      <axis>
        <xyz>1 0 0</xyz>
        <mimic joint='drive_joint'>
          <multiplier>1</multiplier>
          <offset>0</offset>
          <reference>0</reference>
        </mimic>
        <limit>
          <lower>0</lower>
          <upper>0.84999999999999998</upper>
          <effort>50</effort>
          <velocity>2</velocity>
        </limit>
        <dynamics>
          <spring_reference>0</spring_reference>
          <spring_stiffness>0</spring_stiffness>
        </dynamics>
      </axis>
    </joint>
    <link name='left_inner_knuckle'>
      <pose relative_to='left_inner_knuckle_joint'>0 0 0 0 0 0</pose>
      <inertial>
        <pose>1.8660078468790699e-06 0.022046784763362099 0.026133467283088501 0 0 0</pose>
        <mass>0.023012578125670601</mass>
        <inertia>
          <ixx>6.0949002427190604e-06</ixx>
          <ixy>6.0665132616007105e-11</ixy>
          <ixz>7.1910267050063497e-11</ixz>
          <iyy>6.0195508437518803e-06</iyy>
          <iyz>-2.7531681299172101e-06</iyz>
          <izz>5.0786200447990301e-06</izz>
        </inertia>
      </inertial>
      <collision name='left_inner_knuckle_collision'>
        <pose>0 0 0 0 0 0</pose>
        <geometry>
          <mesh>
            <scale>1 1 1</scale>
            <uri>model://xarm_description/meshes/gripper/xarm/left_inner_knuckle.obj</uri>
          </mesh>
        </geometry>
        <surface>
          <contact>
            <ode />
          </contact>
          <friction>
            <ode />
          </friction>
        </surface>
      </collision>
      <visual name='left_inner_knuckle_visual'>
        <pose>0 0 0 0 0 0</pose>
        <geometry>
          <mesh>
            <scale>1 1 1</scale>
            <uri>model://xarm_description/meshes/gripper/xarm/left_inner_knuckle.obj</uri>
          </mesh>
        </geometry>
        <material>
          <diffuse>0.941250026 0.941250026 0.941250026 1</diffuse>
          <ambient>0.941250026 0.941250026 0.941250026 1</ambient>
        </material>
      </visual>

    </link>
    <joint name='right_inner_knuckle_joint' type='revolute'>
      <pose relative_to='link7'>0 -0.02 0.074097999999999997 0 0 0</pose>
      <parent>link7</parent>
      <child>right_inner_knuckle</child>
      <axis>
        <xyz>-1 0 0</xyz>
        <mimic joint='drive_joint'>
          <multiplier>1</multiplier>
          <offset>0</offset>
          <reference>0</reference>
        </mimic>
        <limit>
          <lower>0</lower>
          <upper>0.84999999999999998</upper>
          <effort>50</effort>
          <velocity>2</velocity>
        </limit>
        <dynamics>
          <spring_reference>0</spring_reference>
          <spring_stiffness>0</spring_stiffness>
        </dynamics>
      </axis>
    </joint>
    <link name='right_inner_knuckle'>
      <pose relative_to='right_inner_knuckle_joint'>0 0 0 0 0 0</pose>
      <inertial>
        <pose>1.866e-06 -0.022047000000000001 0.026133 0 0 0</pose>
        <mass>0.023012999999999999</mass>
        <inertia>
          <ixx>6.0948999999999999e-06</ixx>
          <ixy>-6.0665000000000005e-11</ixy>
          <ixz>7.191e-11</ixz>
          <iyy>6.0197000000000001e-06</iyy>
          <iyz>2.7530999999999999e-06</iyz>
          <izz>5.0784000000000004e-06</izz>
        </inertia>
      </inertial>
      <collision name='right_inner_knuckle_collision'>
        <pose>0 0 0 0 0 0</pose>
        <geometry>
          <mesh>
            <scale>1 1 1</scale>
            <uri>model://xarm_description/meshes/gripper/xarm/right_inner_knuckle.obj</uri>
          </mesh>
        </geometry>
        <surface>
          <contact>
            <ode />
          </contact>
          <friction>
            <ode />
          </friction>
        </surface>
      </collision>
      <visual name='right_inner_knuckle_visual'>
        <pose>0 0 0 0 0 0</pose>
        <geometry>
          <mesh>
            <scale>1 1 1</scale>
            <uri>model://xarm_description/meshes/gripper/xarm/right_inner_knuckle.obj</uri>
          </mesh>
        </geometry>
        <material>
          <diffuse>0.941250026 0.941250026 0.941250026 1</diffuse>
          <ambient>0.941250026 0.941250026 0.941250026 1</ambient>
        </material>
      </visual>

    </link>
    <joint name='right_outer_knuckle_joint' type='revolute'>
      <pose relative_to='link7'>0 -0.035000000000000003 0.059097999999999998 0 0 0</pose>
      <parent>link7</parent>
      <child>right_outer_knuckle</child>
      <axis>
        <xyz>-1 0 0</xyz>
        <mimic joint='drive_joint'>
          <multiplier>1</multiplier>
          <offset>0</offset>
          <reference>0</reference>
        </mimic>
        <limit>
          <lower>0</lower>
          <upper>0.84999999999999998</upper>
          <effort>50</effort>
          <velocity>2</velocity>
        </limit>
        <dynamics>
          <spring_reference>0</spring_reference>
          <spring_stiffness>0</spring_stiffness>
        </dynamics>
      </axis>
    </joint>
    <link name='right_outer_knuckle'>
      <pose relative_to='right_outer_knuckle_joint'>0 0 0 0 0 0</pose>
      <inertial>
        <pose>-3.1669000000000002e-14 -0.021558999999999998 0.015181 0 0 0</pose>
        <mass>0.033618000000000002</mass>
        <inertia>
          <ixx>1.9111e-05</ixx>
          <ixy>-1.8789000000000001e-17</ixy>
          <ixz>1.0986e-17</ixz>
          <iyy>6.6255999999999997e-06</iyy>
          <iyz>7.3007999999999996e-06</iyz>
          <izz>1.3185e-05</izz>
        </inertia>
      </inertial>
      <collision name='right_outer_knuckle_collision'>
        <pose>0 0 0 0 0 0</pose>
        <geometry>
          <mesh>
            <scale>1 1 1</scale>
            <uri>model://xarm_description/meshes/gripper/xarm/right_outer_knuckle.obj</uri>
          </mesh>
        </geometry>
        <surface>
          <contact>
            <ode />
          </contact>
          <friction>
            <ode />
          </friction>
        </surface>
      </collision>
      <visual name='right_outer_knuckle_visual'>
        <pose>0 0 0 0 0 0</pose>
        <geometry>
          <mesh>
            <scale>1 1 1</scale>
            <uri>model://xarm_description/meshes/gripper/xarm/right_outer_knuckle.obj</uri>
          </mesh>
        </geometry>
        <material>
          <diffuse>0.941250026 0.941250026 0.941250026 1</diffuse>
          <ambient>0.941250026 0.941250026 0.941250026 1</ambient>
        </material>
      </visual>

    </link>
    <joint name='right_finger_joint' type='revolute'>
      <pose relative_to='right_outer_knuckle'>0 -0.035465000000000003 0.042039 0 0 0</pose>
      <parent>right_outer_knuckle</parent>
      <child>right_finger</child>
      <axis>
        <xyz>1 0 0</xyz>
        <mimic joint='drive_joint'>
          <multiplier>1</multiplier>
          <offset>0</offset>
          <reference>0</reference>
        </mimic>
        <limit>
          <lower>0</lower>
          <upper>0.84999999999999998</upper>
          <effort>50</effort>
          <velocity>2</velocity>
        </limit>
        <dynamics>
          <spring_reference>0</spring_reference>
          <spring_stiffness>0</spring_stiffness>
        </dynamics>
      </axis>
    </joint>
    <link name='right_finger'>
      <pose relative_to='right_finger_joint'>0 0 0 0 0 0</pose>
      <inertial>
        <pose>2.5617999999999999e-14 0.016413000000000001 0.029257999999999999 0 0 0</pose>
        <mass>0.048304</mass>
        <inertia>
          <ixx>1.7493e-05</ixx>
          <ixy>-5.0013999999999996e-19</ixy>
          <ixz>-7.5078999999999999e-18</ixz>
          <iyy>1.7224999999999999e-05</iyy>
          <iyz>-4.6434999999999997e-06</iyz>
          <izz>5.1466e-06</izz>
        </inertia>
      </inertial>
      <collision name='right_finger_collision'>
        <pose>0 0 0 0 0 0</pose>
        <geometry>
          <mesh>
            <scale>1 1 1</scale>
            <uri>model://xarm_description/meshes/gripper/xarm/right_finger.obj</uri>
          </mesh>
        </geometry>
        <surface>
          <contact>
            <ode />
          </contact>
          <friction>
            <ode />
          </friction>
        </surface>
      </collision>
      <visual name='right_finger_visual'>
        <pose>0 0 0 0 0 0</pose>
        <geometry>
          <mesh>
            <scale>1 1 1</scale>
            <uri>model://xarm_description/meshes/gripper/xarm/right_finger.obj</uri>
          </mesh>
        </geometry>
        <material>
          <diffuse>0.941250026 0.941250026 0.941250026 1</diffuse>
          <ambient>0.941250026 0.941250026 0.941250026 1</ambient>
        </material>
      </visual>
    </link>
    <frame name='joint_tcp' attached_to='xarm_gripper_base_link'>
      <pose>0 0 0.17199999999999999 0 0 0</pose>
    </frame>
    <frame name='link_tcp' attached_to='joint_tcp'>
      <pose>0 0 0 0 0 0</pose>
    </frame>
    <frame name='gripper_fix' attached_to='link_eef'>
      <pose>0 0 0 0 0 0</pose>
    </frame>
    <frame name='xarm_gripper_base_link' attached_to='gripper_fix'>
      <pose>0 0 0 0 0 0</pose>
    </frame>
    <frame name='joint_eef' attached_to='link7'>
      <pose>0 0 0 0 0 0</pose>
    </frame>
    <frame name='link_eef' attached_to='joint_eef'>
      <pose>0 0 0 0 0 0</pose>
    </frame>
  </model>
</sdf>